Workbook
Name anak: 'ENTRI DATA'!$G:$G
Name anak_C: 'ENTRI DATA'!$G$4:$G$24
Name c_jukot: 'ENTRI DATA'!$R$4:$R$24
Name dada: 'ENTRI DATA'!$D$4:$U$19
Name dakung: 'ENTRI DATA'!$A$4:$U$19
Name data: 'ENTRI DATA'!$D$4:$U$24
Name g_gapok: KUNCI!$G$25
Name g_keluarga: KUNCI!$K$25
Name g_tjab: KUNCI!#REF!
Name gajip: 'ENTRI DATA'!$H:$H
Name gapok: 'ENTRI DATA'!$H$4:$H$19
Name gapok_c: 'ENTRI DATA'!$H$4:$H$24
Name gapokC: 'ENTRI DATA'!$H$4:$H$19
Name gbul: KUNCI!$R$25
Name gol: 'ENTRI DATA'!$D:$D
Name gol_C: 'ENTRI DATA'!$D$4:$D$24
Name golC: 'ENTRI DATA'!$D$4:$D$19
Name golong: 'ENTRI DATA'!$D$4:$D$19
Name gpjak: KUNCI!$Q$25
Name gtjab: KUNCI!$L$25
Name gtmum: KUNCI!$M$25
Name gtras: KUNCI!$P$25
Name hasil_kotor: KUNCI!$T$5
Name istri: 'ENTRI DATA'!$F:$F
Name istri_C: 'ENTRI DATA'!$F$4:$F$24
Name iwp: 'ENTRI DATA'!$S:$S
Name iwpC1: 'ENTRI DATA'!$S$4:$S$24
Name iwpc8: 'ENTRI DATA'!$T$4:$T$24
Name iwpsen: 'ENTRI DATA'!$T:$T
Name jml_diminta: 'SPP1'!$E$29
Name jml_kotor: KUNCI!$Y$5
Name peg: 'ENTRI DATA'!$E:$E
Name peg_c: 'ENTRI DATA'!$E$4:$E$24
Name terss: 'SPP1'!$E$24
Name tuber: 'ENTRI DATA'!$O:$O
Name tubul: 'ENTRI DATA'!$Q:$Q
Name tufung: 'ENTRI DATA'!$M:$M
Name tujak: 'ENTRI DATA'!$P:$P
Name tumum: 'ENTRI DATA'!$L:$L
Name tun_esel: 'ENTRI DATA'!$K$4:$K$24
Name tuna: 'ENTRI DATA'!$J:$J
Name tuna_c: 'ENTRI DATA'!$J$4:$J$24
Name tunc_ber: 'ENTRI DATA'!$O$4:$O$24
Name tunc_bulat: 'ENTRI DATA'!$Q$4:$Q$24
Name tunc_esel: 'ENTRI DATA'!$K$4:$K$24
Name tunc_fu: 'ENTRI DATA'!$M$4:$M$24
Name tunc_paj: 'ENTRI DATA'!$P$4:$P$24
Name tunc_um: 'ENTRI DATA'!$L$4:$L$24
Name tunce_sus: 'ENTRI DATA'!$N$4:$N$24
Name tunis: 'ENTRI DATA'!$I:$I
Name tunis_C: 'ENTRI DATA'!$I$4:$I$24
Name tusel: 'ENTRI DATA'!$K:$K
Name tusus: 'ENTRI DATA'!$N:$N

Sheet SPP1
A1: PEMERINTAH DAERAH KABUPATEN WONOSOBO
A2: KECAMATAN WATUMALANG
A3: SURAT PERMINTAAN PEMBAYARAN LANGSUNG GAJI DAN TUNJANGAN
A4: (SPP-LS-GAJI-TUNJANGAN)
A5: Nomor :
A6: SPP1
A7: SURAT PENGANTAR
A9: Kepada Yth.
A10: Pengguna Anggaran
A11: Kecamatan Watumalang
A13: Di -
B14: WATUMALANG
A16: Dengan memperhatikan Peraturan Bupati Wonosobo No. 40 Tahun 2017, tentang penjabaran APBD, Bersama ini kami mengajukan Surat Permintaan Pembayaran langsung gaji Sebagai berikut :
A18: a. | B18: Urusan Pemerintahan | E18: : 4.01 (Urusan Pemerintahan Fungsi Penunjang Administrasi Pemerintahan)
A19: b. | B19: SKPD | E19: : 4.01.09.01 Kecamatan Watumalang
A20: c. | B20: Tahun Anggaran | E20: : 2025
A21: d. | B21: Dasar Pengeluaran SPD Nomor | E21: :
E22: :
E23: :
A24: e. | B24: Jumlah Sisa Dana SPD | E24: ='SPP2'!J10 -> 2477569814
B25: {=PROPER([1]!terbilang(terss)&" rupiah")} -> #NAME?
A26: f. | B26: Untuk Keperluan Bulan | E26: MEI 2025
A27: g. | B27: Nama Pembantu Bendahara | E27: `
B28: Pengeluaran Untuk Urusan Gaji | E28: : SOLEH
A29: h. | B29: Jumlah Pembayaran yang diminta | E29: =SPM!L30 -> 6967909
B30: {=PROPER([1]!terbilang(jml_diminta)&" rupiah")} -> #NAME?
A32: i. | B32: Nama dan nomor rekening Bank | E32: : BANK JATENG | H32: 1023000364
G35: Watumalang, 21 April 2025
G37: Pembantu Bendahara Pengeluaran
B38: Bendahara Pengeluaran, | G38: Untuk Urusan Gaji,
B42: DEWI ASMARANI H., A.Md | G42: SOLEH
B43: NIP. 19930702 202012 2 010 | G43: NIP. 19710815 201212 1 001

Sheet SPP2
A1: PEMERINTAH DAERAH KABUPATEN WONOSOBO
A2: KECAMATAN WATUMALANG
A3: SURAT PERMINTAAN PEMBAYARAN LANGSUNG GAJI DAN TUNJANGAN
A4: (SPP-LS-GAJI-TUNJANGAN)
A5: ='SPP1'!A5 -> Nomor :
A6: SPP2
A7: RINGKASAN
A9: RINGKASAN DPA-/ DPPA-/ DPAL-SKPD
A10: JUMLAH DANA DPA-SKPD/ DPPA-SKPD/ DPAL-SKPD | I10: Rp | J10: 2477569814 | K10: I
A11: RINGKASAN SPD
A12: No. Urut | B12: Nomor SPD | F12: Tanggal SPD | I12: Jumlah Dana
A13: 1. | B13: 53/4.019.1/SPD /2023 | F13: 45280 | I13: Rp | J13: 73463154
A14: 2. | B14: 54/4.019.1/SPD /2024 | F14: 45314 | I14: Rp | J14: 73702390
A15: 3. | B15: 55/4.019.1/SPD /2024 | F15: 45344 | I15: Rp | J15: 79210549
A16: 4.
A17: 5.
A18: 6.
A19: 7.
A20: 8
A21: Jumlah | I21: Rp | J21: =J13+J14+J15 -> 226376093 | K21: II
A22: Sisa Dana yang belum di SPD-kan ( I - II ) | I22: Rp | J22: =J10-J21 -> 2251193721
A24: RINGKASAN BELANJA
A25: Belanja UP/ GU | I25: Rp | J25: 0
A26: SP2D Peruntukan LS Pembayaran Gaji dan Tunjangan s/d Bln Lalu | I26: Rp | J26: =J13+J14 -> 147165544
A27: SP2D Peruntukan LS Pembayaran Gaji dan Tunjangan s/d Bln ini | I27: Rp | J27: =J15 -> 79210549
A28: JUMLAH | I28: Rp | J28: =J26+J27 -> 226376093 | K28: III
A29: Sisa SPD yang telah diterbitkan, belum dibelanjakan ( II - III ) | I29: Rp | J29: =J21-J28 -> 0
N30: =J26 -> 147165544
H31: ='SPP1'!G35 -> Watumalang, 21 April 2025 | N31: 86979098
G32: Watumalang, 05 Nopember 2009
B33: Bendahara Pengeluaran, | G33: Pembantu Bendahara Pengeluaran | N33: =J27+N30 -> 226376093
G34: Untuk Urusan Gaji,
A38: DEWI ASMARANI H., A.Md | G38: ='SPP1'!G42 -> SOLEH
A39: NIP. 19930702 202012 2 010 | G39: ='SPP1'!G43 -> NIP. 19710815 201212 1 001

Sheet SPP3
A1: PEMERINTAH DAERAH KABUPATEN WONOSOBO
A2: KECAMATAN WATUMALANG
A3: SURAT PERMINTAAN PEMBAYARAN LANGSUNG GAJI DAN TUNJANGAN
A4: (SPP-LS-GAJI-TUNJANGAN)
A5: ='SPP1'!A5 -> Nomor :
A6: SPP3
A8: R I N C I A N
A10: RENCANA PENGGUNAAN DANA
A11: BULAN : | B11: MARET 2025
A13: No. | B13: KODE REKENING | E13: URAIAN | H13: JUMLAH
H14: (Rp)
A15: 1 | B15: 1.20.1.20.13.00.00.5.1.1.01.01. | E15: Gaji Pokok | H15: =[2]KUNCI!H8 -> 59506800
A16: 2 | B16: 1.20.1.20.13.00.00.5.1.1.01.02. | E16: Tunjangan Keluarga | H16: =[2]KUNCI!K8 -> 5647280
A17: 3 | B17: 1.20.1.20.13.00.00.5.1.1.01.03. | E17: Tunjangan Jabatan | H17: =[2]KUNCI!N8 -> 5920000
A18: 4 | E18: Tunjangan Fungsional
A19: 5 | B19: 1.20.1.20.13.00.00.5.1.1.01.05. | E19: Tunjangan Umum | H19: =[2]KUNCI!L8 -> 1080000
A20: 6 | B20: 1.20.1.20.13.00.00.5.1.1.01.06. | E20: Tunjangan Beras | H20: =[2]KUNCI!W8 -> 3041640
A21: 7 | B21: 1.20.1.20.13.00.00.5.1.1.01.07. | E21: Tunjangan PPh | H21: =[2]KUNCI!Q8 -> 172487
A22: 8 | B22: 1.20.1.20.13.00.00.5.1.1.01.08. | E22: Pembulatan Gaji | H22: =[2]KUNCI!S8 -> 547
A24: JUMLAH | H24: =SUM(H15:J23) -> 75368754
E26: ='SPP1'!G35 -> Watumalang, 21 April 2025
E28: Pembantu Bendahara Pengeluaran
A29: Bendahara Pengeluaran, | F29: Untuk Urusan Gaji,
B32: ='SPP1'!B42:E42 -> DEWI ASMARANI H., A.Md | E32: ='SPP1'!G42 -> SOLEH
B33: ='SPP1'!B43:E43 -> NIP. 19930702 202012 2 010 | E33: ='SPP1'!G43 -> NIP. 19710815 201212 1 001

Sheet SPM
I1: K A B U P A T E N W O N O S O B O
I2: SURAT PERINTAH MEMBAYAR
I3: TAHUN ANGGARAN 2025
Q4: Nomor SPM : SPM-02/Ls/G/7.01.0.00.0.00.05/2024
A5: 1
A6: KUASA BENDAHARAWAN UMUM DAERAH KABUPATEN WONOSOBO | N6: Potongan - Potongan :
A7: Supaya menerbitkan SP2D kepada | H7: :
A8: S K P D | H8: : | I8: KECAMATAN WATUMALANG | N8: No. | O8: Uraian ( No. Rekening ) | Q8: Jumlah | S8: Keterangan
A9: Bendahara Pengeluaran | H9: : | I9: DEWI ASMARANI H., A.Md | N9: 1 | O9: Iuran Wajib Pegawai 1 % | Q9: Rp. | R9: =KUNCI!W25 -> 71709
H10: : | N10: 1 | O10: Iuran Wajib Pegawai 8 % | Q10: Rp. | R10: =KUNCI!X25 -> 0
A11: No. Rekening Bank / Khusus Gaji | H11: : | I11: 1023000364 | J11: ='SPP1'!E28 -> : SOLEH | N11: =N9+1 -> 2 | O11: Tabungan Perumahan | Q11: Rp. | R11: =[2]KUNCI!AC8 -> 0
N12: =N11+1 -> 3 | O12: PPH Pasal 21 | Q12: Rp. | R12: =gpjak -> 0
A13: N P W P | N13: =N12+1 -> 4 | O13: Lain - lain | Q13: Rp.
A14: Dasar Pembayaran No. Tanggal SPD | H14: : | I14: 02/4.019.1/SPD/2024 TGL. 22 Februari 2024
A15: Pembayaran Belanja Pegawai ( Gaji Bulan Maret2024 )
A17: 1. | B17: Belanja Tidak Langsung | O17: Jumlah Potongan | Q17: Rp. | R17: =SUM(R9:R16) -> 71709
A18: 2. | B18: Belanja Langsung | N18: Informasi : (Tidak mengurangi jumlah pembayaran SPM )
A19: Pembebanan pada Kode Rekening :
A20: 1.20.1.20.13.00.00.5.1.1.01.01. | I20: Gaji Pokok | K20: Rp. | L20: =g_gapok -> 5717600 | N20: No. | O20: Uraian ( No. Rekening ) | Q20: Jumlah | S20: Keterangan
A21: 1.20.1.20.13.00.00.5.1.1.01.02. | I21: Tunjangan Keluarga | K21: Rp. | L21: =g_keluarga -> 743288 | N21: 1 | O21: P P N | Q21: Rp.
A22: 1.20.1.20.13.00.00.5.1.1.01.03. | I22: Tunjangan Jabatan | K22: Rp. | L22: =gtjab -> 0 | N22: 2 | O22: P P H | Q22: Rp.
I23: Tunjangan Fungsional | K23: Rp. | L23: 0
A24: 1.20.1.20.13.00.00.5.1.1.01.05. | I24: Tunjangan Umum | K24: Rp. | L24: =gtmum -> 0 | O24: Jumlah | Q24: Rp.
A25: 1.20.1.20.13.00.00.5.1.1.01.06. | I25: Tunjangan Beras | K25: Rp. | L25: =gtras -> 506940 | O25: Jumlah yang dibayarkan | Q25: . . . . . . . . . . . . . . . . . . . . . . . . . . . . . . . . . . . . . | T25: =L30-R17 -> 6896200
A26: 1.20.1.20.13.00.00.5.1.1.01.07. | I26: Tunjangan PPh | K26: Rp. | L26: =gpjak -> 0 | N26: Uang sejumlah : | P26: {=PROPER([1]!terbilang(T25)&" rupiah")} -> #NAME?
A27: 1.20.1.20.13.00.00.5.1.1.01.08. | I27: Pembulatan Gaji | K27: Rp. | L27: =gbul -> 81
A30: Jumlah SPP yang diminta | K30: Rp. | L30: =SUM(L20:L29) -> 6967909 | R30: ='SPP1'!G35 -> Watumalang, 21 April 2025
A32: Nomor dan Tanggal SPP | H32: : | I32: 912/002/2024 tgl 22 Februari 2024 | R32: CAMAT WATUMALANG
R38: AMIR MA'RUF, SE
R39: NIP. 196703231986081001
I40: SPM ini sah apabila telah di tandatangani dan distempel oleh kepala SKPD

Sheet PERBEDAAN
A1: DAFTAR PERBEDAAN JUMLAH PEGAWAI DAN PEMBAYARAN
A3: GAJI BULAN | F3: =": "&'SPP1'!E26 -> : MEI 2025
A4: BADAN / DINAS KANTOR | F4: : KECAMATAN WATUMALANG
A5: KODE REKENING | F5: : 2.01.13.1.1.03.2
B6: Golongan/ | D6: I. Bulan : (diisi bulan lalu) | I6: II. Bulan : (diisi bulan berkenaan) | N6: III. PERBEDAAN
A7: No | B7: Ruang | D7: PEG. | E7: ISTRI | F7: ANAK | G7: JIWA | H7: JML. KOTOR | I7: PEG. | J7: ISTRI | K7: ANAK | L7: JIWA | M7: JML. KOTOR | N7: PEGAWAI | P7: ISTRI | R7: ANAK | T7: JIWA | V7: JUMLAH KOTOR
N8: TAMBAH | O8: KURANG | P8: TAMBAH | Q8: KURANG | R8: TAMBAH | S8: KURANG | T8: TAMBAH | U8: KURANG | V8: TAMBAH | W8: KURANG
A9: 1 | B9: 2 | D9: 3 | E9: 4 | F9: 5 | G9: 6 | H9: 7 | I9: 8 | J9: 9 | K9: 10 | L9: 11 | M9: 12 | N9: 13 | O9: 14 | P9: 15 | Q9: 16 | R9: 17 | S9: 18 | T9: 19 | U9: 20 | V9: 21 | W9: 22
A10: 1 | B10: Gol. I/a | C10: I | G10: =SUM(D10:F10) -> 0 | I10: =SUMIF(gol_C,C10,peg_c) -> 0 | J10: =SUMIF(gol_C,C10,istri_C) -> 0 | K10: =SUMIF(gol_C,C10,anak_C) -> 0 | L10: =SUM(I10:K10) -> 0 | M10: =SUMIF(gol_C,C10,c_jukot) -> 0 | O10: =D10-I10 -> 0 | W10: =H10-M10 -> 0
B11: Gol. I/b | C11: II | G11: =SUM(D11:F11) -> 0 | I11: =SUMIF(gol_C,C11,peg_c) -> 0 | J11: =SUMIF(gol_C,C11,istri_C) -> 0 | K11: =SUMIF(gol_C,C11,anak_C) -> 0 | L11: =SUM(I11:K11) -> 0 | M11: =SUMIF(gol_C,C11,c_jukot) -> 0 | O11: =D11-I11 -> 0 | W11: =H11-M11 -> 0
B12: Gol. I/c | C12: III | G12: =SUM(D12:F12) -> 0 | I12: =SUMIF(gol_C,C12,peg_c) -> 0 | J12: =SUMIF(gol_C,C12,istri_C) -> 0 | K12: =SUMIF(gol_C,C12,anak_C) -> 0 | L12: =SUM(I12:K12) -> 0 | M12: =SUMIF(gol_C,C12,c_jukot) -> 0 | O12: =D12-I12 -> 0 | W12: =H12-M12 -> 0
B13: Gol. I/d | C13: IV | G13: =SUM(D13:F13) -> 0 | I13: =SUMIF(gol_C,C13,peg_c) -> 0 | J13: =SUMIF(gol_C,C13,istri_C) -> 0 | K13: =SUMIF(gol_C,C13,anak_C) -> 0 | L13: =SUM(I13:K13) -> 0 | M13: =SUMIF(gol_C,C13,c_jukot) -> 0 | O13: =D13-I13 -> 0 | W13: =H13-M13 -> 0
B14: Jumlah Gol I | D14: =SUM(D10:D13) -> 0 | E14: =SUM(E10:E13) -> 0 | F14: =SUM(F10:F13) -> 0 | G14: =SUM(D14:F14) -> 0 | H14: =SUM(H10:H13) -> 0 | I14: =SUM(I10:I13) -> 0 | J14: =SUM(J10:J13) -> 0 | K14: =SUM(K10:K13) -> 0 | L14: =SUM(I14:K14) -> 0 | M14: =SUM(M10:M13) -> 0 | N14: =SUM(N10:N13) -> 0 | O14: =SUM(O10:O13) -> 0 | P14: =SUM(P10:P13) -> 0 | Q14: =SUM(Q10:Q13) -> 0 | R14: =SUM(R10:R13) -> 0 | S14: =SUM(S10:S13) -> 0 | T14: =SUM(T10:T13) -> 0 | U14: =SUM(U10:U13) -> 0 | V14: =V10+V11+V12+V13 -> 0 | W14: =SUM(W10:W13) -> 0
A15: 2 | B15: Gol. II/a | C15: V | G15: =SUM(D15:F15) -> 0 | I15: =SUMIF(gol_C,C15,peg_c) -> 0 | J15: =SUMIF(gol_C,C15,istri_C) -> 0 | K15: =SUMIF(gol_C,C15,anak_C) -> 0 | L15: =SUM(I15:K15) -> 0 | M15: =SUMIF(gol_C,C15,c_jukot) -> 0 | W15: =H15-M15 -> 0
B16: Gol. II/b | C16: VI | G16: =SUM(D16:F16) -> 0 | I16: =SUMIF(gol_C,C16,peg_c) -> 0 | J16: =SUMIF(gol_C,C16,istri_C) -> 0 | K16: =SUMIF(gol_C,C16,anak_C) -> 0 | L16: =SUM(I16:K16) -> 0 | M16: =SUMIF(gol_C,C16,c_jukot) -> 0 | W16: =H16-M16 -> 0
B17: Gol. II/c | C17: II/C | D17: =[3]PERBEDAAN!$I$17 -> 2 | E17: =[3]PERBEDAAN!$J$17 -> 2 | F17: =[3]PERBEDAAN!$K$17 -> 3 | G17: =SUM(D17:F17) -> 7 | H17: =[3]PERBEDAAN!$M$17 -> 7677909 | I17: =SUMIF(gol_C,C17,peg_c) -> 2 | J17: =SUMIF(gol_C,C17,istri_C) -> 2 | K17: =SUMIF(gol_C,C17,anak_C) -> 3 | L17: =SUM(I17:K17) -> 7 | M17: =SUMIF(gol_C,C17,c_jukot) -> 7677909 | W17: =H17-M17 -> 0
B18: Gol. II/d | C18: VIII | G18: =SUM(D18:F18) -> 0 | I18: =SUMIF(gol_C,C18,peg_c) -> 0 | J18: =SUMIF(gol_C,C18,istri_C) -> 0 | K18: =SUMIF(gol_C,C18,anak_C) -> 0 | L18: =SUM(I18:K18) -> 0 | M18: =SUMIF(gol_C,C18,c_jukot) -> 0 | W18: =H18-M18 -> 0
B19: Jumlah Gol II | D19: =SUM(D15:D18) -> 2 | E19: =SUM(E15:E18) -> 2 | F19: =SUM(F15:F18) -> 3 | G19: =SUM(D19:F19) -> 7 | H19: =SUM(H15:H18) -> 7677909 | I19: =SUM(I15:I18) -> 2 | J19: =SUM(J15:J18) -> 2 | K19: =SUM(K15:K18) -> 3 | L19: =SUM(I19:K19) -> 7 | M19: =SUM(M15:M18) -> 7677909 | N19: =SUM(N15:N18) -> 0 | O19: =SUM(O15:O18) -> 0 | P19: =SUM(P15:P18) -> 0 | Q19: =SUM(Q15:Q18) -> 0 | R19: =SUM(R15:R18) -> 0 | S19: =SUM(S15:S18) -> 0 | T19: =SUM(T15:T18) -> 0 | U19: 0 | V19: =SUM(V15:V18) -> 0 | W19: =W15+W16+W17+W18 -> 0
A20: 3 | B20: Gol. III/a | C20: IX | G20: =SUM(D20:F20) -> 0 | I20: =SUMIF(gol_C,C20,peg_c) -> 0 | J20: =SUMIF(gol_C,C20,istri_C) -> 0 | K20: =SUMIF(gol_C,C20,anak_C) -> 0 | L20: =SUM(I20:K20) -> 0 | M20: =SUMIF(gol_C,C20,c_jukot) -> 0 | N20: 0 | O20: 0 | P20: 0 | Q20: 0 | S20: 0 | T20: 0 | U20: 0 | V20: 0 | W20: =H20-M20 -> 0
B21: Gol. III/b | C21: X | G21: =SUM(D21:F21) -> 0 | I21: =SUMIF(gol_C,C21,peg_c) -> 0 | J21: =SUMIF(gol_C,C21,istri_C) -> 0 | K21: =SUMIF(gol_C,C21,anak_C) -> 0 | L21: =SUM(I21:K21) -> 0 | M21: =SUMIF(gol_C,C21,c_jukot) -> 0 | N21: =I21-D21 -> 0 | O21: 0 | P21: =J21-E21 -> 0 | Q21: 0 | R21: =K21-F21 -> 0 | S21: 0 | T21: =L21-G21 -> 0 | U21: 0 | V21: 0 | W21: =H21-M21 -> 0
B22: Gol. III/c | C22: XI | G22: =SUM(D22:F22) -> 0 | I22: =SUMIF(gol_C,C22,peg_c) -> 0 | J22: =SUMIF(gol_C,C22,istri_C) -> 0 | K22: =SUMIF(gol_C,C22,anak_C) -> 0 | L22: =SUM(I22:K22) -> 0 | M22: =SUMIF(gol_C,C22,c_jukot) -> 0 | N22: 0 | O22: 0 | P22: 0 | Q22: 0 | R22: 0 | S22: 0 | T22: 0 | U22: 0 | W22: =H22-M22 -> 0
B23: Gol. III/d | C23: XII | G23: =SUM(D23:F23) -> 0 | I23: =SUMIF(gol_C,C23,peg_c) -> 0 | J23: =SUMIF(gol_C,C23,istri_C) -> 0 | K23: =SUMIF(gol_C,C23,anak_C) -> 0 | L23: =SUM(I23:K23) -> 0 | M23: =SUMIF(gol_C,C23,c_jukot) -> 0 | N23: 0 | O23: 0 | P23: 0 | Q23: 0 | R23: 0 | S23: 0 | T23: 0 | U23: 0 | V23: 0 | W23: =H23-M23 -> 0
B24: Jumlah Gol III | D24: =SUM(D20:D23) -> 0 | E24: =SUM(E20:E23) -> 0 | F24: =SUM(F20:F23) -> 0 | G24: =SUM(D24:F24) -> 0 | H24: =SUM(H20:H23) -> 0 | I24: =SUM(I20:I23) -> 0 | J24: =SUM(J20:J23) -> 0 | K24: =SUM(K20:K23) -> 0 | L24: =SUM(I24:K24) -> 0 | M24: =SUM(M20:M23) -> 0 | N24: =SUM(N20:N23) -> 0 | O24: =SUM(O20:O23) -> 0 | P24: =SUM(P20:P23) -> 0 | Q24: =SUM(Q20:Q23) -> 0 | R24: =SUM(R20:R23) -> 0 | S24: =SUM(S20:S23) -> 0 | T24: =SUM(T20:T23) -> 0 | U24: =SUM(U20:U23) -> 0 | V24: =V20+V21+V22+V23 -> 0 | W24: =SUM(W20:W23) -> 0
A25: 4 | B25: Gol. IV/a | C25: IV/A | G25: =SUM(D25:F25) -> 0 | I25: =SUMIF(gol_C,C25,peg_c) -> 0 | J25: =SUMIF(gol_C,C25,istri_C) -> 0 | K25: =SUMIF(gol_C,C25,anak_C) -> 0 | L25: =SUM(I25:K25) -> 0 | M25: =SUMIF(gol_C,C25,c_jukot) -> 0 | N25: 0 | O25: =D25-I25 -> 0 | P25: 0 | Q25: =E25-J25 -> 0 | R25: 0 | S25: =F25-K25 -> 0 | T25: 0 | U25: =G25-L25 -> 0 | V25: 0 | W25: =H25-M25 -> 0
B26: Gol. IV/b | C26: IV/B | G26: =SUM(D26:F26) -> 0 | I26: =SUMIF(gol_C,C26,peg_c) -> 0 | J26: =SUMIF(gol_C,C26,istri_C) -> 0 | K26: =SUMIF(gol_C,C26,anak_C) -> 0 | L26: =SUM(I26:K26) -> 0 | M26: =SUMIF(gol_C,C26,c_jukot) -> 0 | N26: 0 | O26: 0 | P26: 0 | Q26: 0 | R26: 0 | S26: 0 | T26: 0 | U26: 0 | V26: 0 | W26: =H26-M26 -> 0
B27: Gol. IV/c | C27: IV/C | G27: =SUM(D27:F27) -> 0 | I27: =SUMIF(gol_C,C27,peg_c) -> 0 | J27: =SUMIF(gol_C,C27,istri_C) -> 0 | K27: =SUMIF(gol_C,C27,anak_C) -> 0 | L27: =SUM(I27:K27) -> 0 | M27: =SUMIF(gol_C,C27,c_jukot) -> 0 | N27: 0 | O27: 0 | P27: 0 | Q27: 0 | R27: 0 | S27: 0 | T27: 0 | U27: 0 | V27: 0 | W27: =H27-M27 -> 0
B28: Gol. IV/d | C28: IV/D | G28: =SUM(D28:F28) -> 0 | I28: =SUMIF(gol_C,C28,peg_c) -> 0 | J28: =SUMIF(gol_C,C28,istri_C) -> 0 | K28: =SUMIF(gol_C,C28,anak_C) -> 0 | L28: =SUM(I28:K28) -> 0 | M28: =SUMIF(gol_C,C28,c_jukot) -> 0 | N28: 0 | O28: 0 | P28: =J28-E28 -> 0 | Q28: 0 | R28: =K28-F28 -> 0 | S28: 0 | T28: =N28+P28+R28 -> 0 | U28: 0 | V28: 0 | W28: =H28-M28 -> 0
B29: Jumlah Gol IV | D29: =SUM(D25:D28) -> 0 | E29: =SUM(E25:E28) -> 0 | F29: =SUM(F25:F28) -> 0 | G29: =SUM(G25:G28) -> 0 | H29: =SUM(H25:H28) -> 0 | I29: =SUM(I25:I28) -> 0 | J29: =SUM(J25:J28) -> 0 | K29: =SUM(K25:K28) -> 0 | L29: =SUM(I29:K29) -> 0 | M29: =SUM(M25:M28) -> 0 | N29: =SUM(N25:N28) -> 0 | O29: =SUM(O25:O28) -> 0 | P29: =SUM(P25:P28) -> 0 | Q29: =SUM(Q25:Q28) -> 0 | R29: =SUM(R25:R28) -> 0 | S29: =SUM(S25:S28) -> 0 | T29: =SUM(T25:T28) -> 0 | ... V29: =SUM(V25:V28) -> 0 | W29: =W25+W26+W27+W28 -> 0
B30: JUMLAH | D30: =SUM(D14+D19+D24+D29) -> 2 | E30: =SUM(E14+E19+E24+E29) -> 2 | F30: =SUM(F14+F19+F24+F29) -> 3 | G30: =SUM(G14+G19+G24+G29) -> 7 | H30: =H14+H19+H24+H29 -> 7677909 | I30: =SUM(I14+I19+I24+I29) -> 2 | J30: =SUM(J14+J19+J24+J29) -> 2 | K30: =SUM(K14+K19+K24+K29) -> 3 | L30: =SUM(L14+L19+L24+L29) -> 7 | M30: =M14+M19+M24+M29 -> 7677909 | N30: =SUM(N14+N19+N24+N29) -> 0 | O30: =SUM(O14+O19+O24+O29) -> 0 | P30: =SUM(P14+P19+P24+P29) -> 0 | Q30: =SUM(Q14+Q19+Q24+Q29) -> 0 | R30: =SUM(R14+R19+R24+R29) -> 0 | S30: =SUM(S14+S19+S24+S29) -> 0 | T30: =SUM(T14+T19+T24+T29) -> 0 | U30: =SUM(U14+U19+U24+U29) -> 0 | V30: =V14+V19++V24 -> 0 | W30: =W14+W19+W24+W29 -> 0
S32: ='SPP1'!G35 -> Watumalang, 21 April 2025
B34: Bendahara Pengeluaran | S34: Pembantu Bendahara Pengeluaran
S35: Untuk Urusan Gaji
B38: DEWI ASMARANI H., A.Md | S38: ='SPP1'!G42 -> SOLEH
B39: NIP. 19930702 202012 2 010 | S39: ='SPP1'!G43 -> NIP. 19710815 201212 1 001

Sheet RINCIAN
B1: DAFTAR : | C1: RINCIAN BELANJA DAN TUNJANGAN PEGAWAI
C2: PEMBAYARAN GAJI / GAJI SUSULAN / KEKURANGAN GAJI
C4: SATUAN KERJA | E4: : | F4: KECAMATAN WATUMALANG
C5: KODE REKENING | E5: : | F5: 2.01.13.1.1.03.2
C6: NPWP | E6: : | F6: -
C7: KAB./KOTA | E7: : | F7: WONOSOBO
C8: BULAN | E8: : | F8: ='SPP1'!E26 -> MEI 2025
C10: Jumlah SPM | E10: : | F10: =D33 -> 7677909
C11: Jumlah Meninggal | E11: : | F11: 0
A13: No. | B13: URAIAN | C13: GOLONGAN | H13: JUMLAH
C14: I | D14: II | F14: III | G14: IV | H14: (I,II,III,IV)
A15: 1 | B15: 2 | C15: 3 | D15: 4 | F15: 5 | G15: 6 | H15: 7(3+4+5+6)
A16: I | B16: JUMLAH ORANG | C16: =SUM(C17:C19) -> 0 | D16: =SUM(D17:D19) -> 7 | F16: =SUM(F17:F19) -> 0 | G16: =SUM(G17:G19) -> 0 | H16: =SUM(H17:H19) -> 7
B17: 1. Pegawai | C17: 0 | D17: =KUNCI!C25 -> 2 | F17: 0 | G17: 0 | H17: =SUM(C17:G17) -> 2
B18: 2. Istri/Suami | C18: =[2]KUNCI!E4 -> 0 | D18: =KUNCI!D25 -> 2 | F18: 0 | G18: 0 | H18: =SUM(C18:G18) -> 2
B19: 3. Anak | C19: =[2]KUNCI!F4 -> 0 | D19: =KUNCI!E25 -> 3 | F19: 0 | G19: 0 | H19: =SUM(C19:G19) -> 3
A20: II | B20: JUMLAH ORANG | D20: =SUM(D21:E22) -> 2 | F20: 0 | G20: 0 | H20: =H21+H22 -> 2
B21: 1. Struktural | C21: 0 | D21: 0 | F21: 0 | G21: 0 | H21: =SUM(C21:G21) -> 0
B22: 2. Fungsional | C22: 0 | D22: 2 | F22: 0 | G22: 0 | H22: =SUM(C22:G22) -> 2
A23: III | B23: JML. GAJI & TUNJ. | C23: =SUM(C24:C31) -> 0 | D23: =SUM(D24:E32) -> 7677909 | F23: =SUM(F24:F31) -> 0 | G23: =SUM(G24:G31) -> 0 | H23: =SUM(H24:H32) -> 7677909
B24: 1. Gaji Pokok | C24: 0 | D24: =KUNCI!G25 -> 5717600 | F24: 0 | G24: 0 | H24: =SUM(C24:G24) -> 5717600
B25: 2. T. Istri/Suami | C25: =[2]KUNCI!I4 -> 0 | D25: =KUNCI!H25 -> 571760 | F25: 0 | G25: =[2]KUNCI!M4 -> 0 | H25: =SUM(C25:G25) -> 571760
B26: 3. Tunjangan Anak | C26: =[2]KUNCI!J4 -> 0 | D26: =KUNCI!I25 -> 171528 | F26: =[2]KUNCI!M4 -> 0 | G26: =[2]KUNCI!N4 -> 0 | H26: =SUM(C26:G26) -> 171528
B27: 4. Tunjangan Umum | C27: 0 | D27: 0 | F27: 0 | G27: 0 | H27: =SUM(C27:G27) -> 0
B28: 5. Tunj. Jab. Struktural | C28: 0 | D28: 0 | F28: 0 | G28: 0 | H28: =SUM(C28:G28) -> 0
B29: 6. Tunj. Fungsional | C29: 0 | D29: =KUNCI!N25 -> 710000 | F29: 0 | G29: 0 | H29: =SUM(C29:G29) -> 710000
B30: 7. Tunj. Khusus | C30: =[2]KUNCI!Q4 -> 0 | D30: =[2]KUNCI!Q5 -> 0 | F30: 0 | G30: 0 | H30: =SUM(C30:G30) -> 0
B31: 8. Pembulatan | C31: 0 | D31: =KUNCI!R25 -> 81 | F31: 0 | G31: 0 | H31: =SUM(C31:G31) -> 81
A32: IV | B32: TUNJ. BERAS | C32: 0 | D32: =KUNCI!P25 -> 506940 | F32: 0 | G32: 0 | H32: =SUM(C32:G32) -> 506940
A33: V | B33: JUMLAH (III+IV) | C33: =C24+C25+C26+C27+C30+C31+C32 -> 0 | D33: =SUM(D24:D32) -> 7677909 | F33: =SUM(F24:F32) -> 0 | G33: =SUM(G24:G32) -> 0 | H33: =SUM(C33:G33) -> 7677909
B34: 1. IWP 1 % | C34: 0 | D34: =KUNCI!W25 -> 71709 | F34: 0 | G34: 0 | H34: =C34+D34+F34+G34 -> 71709
B35: 2. IWP 8 % | C35: 0 | D35: 0 | F35: 0 | G35: 0 | H35: =C35+D35+F35+G35 -> 0
B36: 3. TAPERUM | C36: =[2]KUNCI!AC4 -> 0 | D36: =[2]KUNCI!AC5 -> 0 | F36: =[2]KUNCI!AC6 -> 0 | G36: =[2]KUNCI!AC7 -> 0 | H36: =C36+D36+F36+G36 -> 0
B37: 4. PPh PASAL 21 | C37: =C30 -> 0 | D37: =D30 -> 0 | F37: =F30 -> 0 | G37: =G30 -> 0 | H37: =C37+D37+F37+G37 -> 0
A38: VI | B38: JML. POTONGAN | C38: =C37+C36+C35+C34 -> 0 | D38: =D37+D36+D35+D34 -> 71709 | F38: =SUM(F34:F37) -> 0 | G38: =SUM(G34:G37) -> 0 | H38: =C38+D38+F38+G38 -> 71709
A39: VII | B39: JML. BERSIH | C39: =C33-C38 -> 0 | D39: =SUM(D33-D38) -> 7606200 | F39: =SUM(F33-F38) -> 0 | G39: =G33-G38 -> 0 | H39: =SUM(H33-H38) -> 7606200
F41: ='SPP1'!G35 -> Watumalang, 21 April 2025
B43: Bendahara Pengeluaran | G43: Pembantu Bendahara Pengeluaran
G44: Untuk Urusan Gaji
B47: ='[2]JML. PEG'!B40 -> DEWI ASMARANI H., A.Md | G47: ='SPP1'!G42 -> SOLEH
...

Sheet JML. PEG
A1: DAFTAR ISIAN JUMLAH PEGAWAI
A2: PER GOLONGAN DAN JABATAN
A3: KANTOR : KECAMATAN WATUMALANG
A5: ="BULAN : "&'ENTRI DATA'!B1 -> BULAN : MEI 2025
A6: GOLONGAN | C6: E S E L O N | H6: TOTAL
C7: I | D7: II | E7: III | F7: IV | G7: STAF
A8: 1 | C8: 2 | D8: 3 | E8: 4 | F8: 5 | G8: 6 | H8: 7
A9: Gol. 17 | B9: 17 | C9: 0 | D9: 0 | E9: 0 | F9: =SUMIF(gol_C,A9,peg_c) -> 0 | G9: =SUMIF(gol_C,B9,peg_c) -> 0 | H9: =SUM(C9:G9) -> 0
A10: Gol. 16 | B10: 16 | C10: 0 | D10: 0 | E10: 0 | F10: =SUMIF(gol_C,A10,peg_c) -> 0 | G10: =SUMIF(gol_C,B10,peg_c) -> 0 | H10: =SUM(C10:G10) -> 0
A11: Gol. 15 | B11: 15 | C11: 0 | D11: 0 | E11: 0 | F11: =SUMIF(gol_C,A11,peg_c) -> 0 | G11: =SUMIF(gol_C,B11,peg_c) -> 0 | H11: =SUM(C11:G11) -> 0
A12: Gol. 14 | B12: 14 | C12: 0 | D12: 0 | E12: 0 | F12: =SUMIF(gol_C,A12,peg_c) -> 0 | G12: =SUMIF(gol_C,B12,peg_c) -> 0 | H12: =SUM(C12:G12) -> 0
A13: Gol. 13 | B13: XIII | C13: 0 | D13: 0 | E13: 0 | F13: =SUMIF(gol_C,A13,peg_c) -> 0 | G13: =SUMIF(gol_C,B13,peg_c) -> 0 | H13: =SUM(C13:G13) -> 0 | I13: 0
A14: Jumlah Golongan IV | C14: =SUM(C9:C13) -> 0 | D14: =SUM(D9:D13) -> 0 | E14: =SUM(E9:E13) -> 0 | F14: =SUM(F9:F13) -> 0 | G14: =SUM(G9:G13) -> 0 | H14: =SUM(H9:H13) -> 0
A15: Gol. 12 | B15: XII | C15: 0 | D15: 0 | E15: =SUMIF(gol_C,A15,peg_c) -> 0 | F15: 0 | G15: =SUMIF(gol_C,B15,peg_c) -> 0 | H15: =SUM(C15:G15) -> 0
A16: Gol. 11 | B16: XI | C16: 0 | D16: 0 | E16: =SUMIF(gol_C,A16,peg_c) -> 0 | F16: 0 | G16: =SUMIF(gol_C,B16,peg_c) -> 0 | H16: =SUM(C16:G16) -> 0
A17: Gol. 10 | B17: X | C17: 0 | D17: 0 | E17: =SUMIF(gol_C,A17,peg_c) -> 0 | F17: 0 | G17: =SUMIF(gol_C,B17,peg_c) -> 0 | H17: =SUM(C17:G17) -> 0
A18: Gol. 9 | B18: IX | C18: 0 | D18: 0 | E18: =SUMIF(gol_C,A18,peg_c) -> 0 | F18: 0 | G18: =SUMIF(gol_C,B18,peg_c) -> 0 | H18: =SUM(C18:G18) -> 0
A19: Jumlah Golongan III | C19: =SUM(C15:C18) -> 0 | D19: =SUM(D15:D18) -> 0 | E19: =SUM(E15:E18) -> 0 | F19: =SUM(F15:F18) -> 0 | G19: =SUM(G15:G18) -> 0 | H19: =SUM(H15:H18) -> 0
A20: Gol. 8 | B20: VIII | C20: 0 | D20: =SUMIF(gol_C,B20,peg_c) -> 0 | E20: 0 | F20: 0 | G20: =SUMIF(gol_C,B20,peg_c) -> 0 | H20: =SUM(C20:G20) -> 0
A21: Gol. 7 | B21: II/C | C21: 0 | D21: 0 | E21: 0 | F21: 0 | G21: =SUMIF(gol_C,B21,peg_c) -> 2 | H21: =SUM(C21:G21) -> 2
A22: Gol. 6 | B22: VI | C22: 0 | D22: =SUMIF(gol_C,B22,peg_c) -> 0 | E22: 0 | F22: 0 | G22: =SUMIF(gol_C,B22,peg_c) -> 0 | H22: =SUM(C22:G22) -> 0
A23: Gol. 5 | B23: V | C23: 0 | D23: =SUMIF(gol_C,B23,peg_c) -> 0 | E23: 0 | F23: 0 | G23: =SUMIF(gol_C,B23,peg_c) -> 0 | H23: =SUM(C23:G23) -> 0
A24: Jumlah Golongan II | C24: =SUM(C20:C23) -> 0 | D24: =SUM(D20:D23) -> 0 | E24: =SUM(E20:E23) -> 0 | F24: =SUM(F20:F23) -> 0 | G24: =SUM(G20:G23) -> 2 | H24: =SUM(H20:H23) -> 2
A25: Gol. 4 | B25: IV | C25: =SUMIF(gol_C,A25,peg_c) -> 0 | D25: 0 | E25: 0 | F25: 0 | G25: =SUMIF(gol_C,B25,peg_c) -> 0 | H25: =SUM(C25:G25) -> 0
A26: Gol. 3 | B26: III | C26: =SUMIF(gol_C,A26,peg_c) -> 0 | D26: 0 | E26: 0 | F26: 0 | G26: =SUMIF(gol_C,B26,peg_c) -> 0 | H26: =SUM(C26:G26) -> 0
A27: Gol. 2 | B27: II | C27: =SUMIF(gol_C,A27,peg_c) -> 0 | D27: 0 | E27: 0 | F27: 0 | G27: =SUMIF(gol_C,B27,peg_c) -> 0 | H27: =SUM(C27:G27) -> 0
A28: Gol. I | B28: I | C28: =SUMIF(gol_C,A28,peg_c) -> 0 | D28: 0 | E28: 0 | F28: 0 | G28: =SUMIF(gol_C,B28,peg_c) -> 0 | H28: =SUM(C28:G28) -> 0
A29: Jumlah Golongan I | C29: =SUM(C25:C28) -> 0 | D29: =SUM(D25:D28) -> 0 | E29: =SUM(E25:E28) -> 0 | F29: =SUM(F25:F28) -> 0 | G29: =SUM(G25:G28) -> 0
A30: Jumlah I s/d IV | C30: =SUM(C14+C19+C24+C29) -> 0 | D30: =SUM(D14+D19+D24+D29) -> 0 | E30: =SUM(E14+E19+E24+E29) -> 0 | F30: =SUM(F14+F19+F24+F29) -> 0 | G30: =SUM(G14+G19+G24+G29) -> 2 | H30: =SUM(H14+H19+H24+H29) -> 2
E33: ='SPP1'!G35 -> Watumalang, 21 April 2025
E34: Pembantu Bendahara Pengeluaran
A35: Bendahara Pengeluaran | E35: Untuk Urusan Gaji
A39: DEWI ASMARANI H., A.Md | E39: ='SPP1'!G42 -> SOLEH
A40: NIP. 19930702 202012 2 010 | E40: ='SPP1'!G43 -> NIP. 19710815 201212 1 001

Sheet KUNCI
A1: UNIT KERJA | B1: GOL | F1: PENGHASILAN | U1: POTONGAN | Z1: JML. BERSIH (21 + 26)
C2: PEGAWAI | D2: S / I | E2: ANAK | F2: JML | G2: GAJI POKOK | H2: SUAMI/ISTRI | I2: T. ANAK | J2: JML (7 s/d 9) | K2: Keluarga | L2: TUNJANGAN | P2: BERAS | Q2: PAJAK | R2: PEMBULATAN | S2: JML (12 s/d 18) | T2: JML (11 + 19) | U2: PAJAK | V2: BPJSKES | W2: I W P 1 % | X2: I W P 8 % | Y2: JML (22 s/d 25)
L3: ESELON | M3: F. UMUM | N3: FUNGSIONAL | O3: KHUSUS
A4: 1 | B4: =A4+1 -> 2 | C4: =B4+1 -> 3 | D4: =C4+1 -> 4 | E4: =D4+1 -> 5 | F4: =E4+1 -> 6 | G4: =F4+1 -> 7 | H4: =G4+1 -> 8 | I4: =H4+1 -> 9 | J4: =I4+1 -> 10 | L4: =J4+1 -> 11 | M4: =L4+1 -> 12 | N4: =M4+1 -> 13 | O4: =N4+1 -> 14 | P4: =O4+1 -> 15 | Q4: =P4+1 -> 16 | R4: =Q4+1 -> 17 | S4: =R4+1 -> 18 | T4: =S4+1 -> 19 | ... Z4: =Y4+1 -> 25
A5: KEC WATUMALANG | B5: IV | C5: =SUM(C6:C9) -> 0 | D5: =SUM(D6:D9) -> 0 | E5: =SUM(E6:E9) -> 0 | F5: =SUM(F6:F9) -> 0 | G5: =SUM(G6:G9) -> 0 | H5: =SUM(H6:H9) -> 0 | I5: =SUM(I6:I9) -> 0 | J5: =G5+H5+I5 -> 0 | K5: =SUM(K6:K9) -> 0 | L5: =SUM(L6:L9) -> 0 | M5: =SUM(M6:M9) -> 0 | N5: =SUM(N6:N9) -> 0 | O5: =SUM(O6:O9) -> 0 | P5: =SUM(P6:P9) -> 0 | Q5: =SUM(Q6:Q9) -> 0 | R5: =SUM(R6:R9) -> 0 | S5: =L5+M5+N5+O5+P5+Q5+R5 -> 0 | T5: =S5+J5 -> 0 | U5: =SUM(U6:U9) -> 0 | V5: =SUM(V6:V9) -> 0 | W5: =SUM(W6:W9) -> 0 | X5: =SUM(X6:X9) -> 0 | Y5: =SUM(U5:X5) -> 0 | Z5: =hasil_kotor-jml_kotor -> 0
B6: IV/A | C6: =SUMIF(gol_C,B6,peg_c) -> 0 | D6: =IFERROR(VLOOKUP(B6,data,3,FALSE), 0) -> 0 | E6: =IFERROR(VLOOKUP(B6,data,4,FALSE), 0) -> 0 | F6: =SUM(C6:E6) -> 0 | G6: =SUMIF(gol_C,B6,gapok_c) -> 0 | H6: =SUMIF(gol_C,B6,tunis_C) -> 0 | I6: =SUMIF(gol_C,B6,tuna_c) -> 0 | J6: =G6+H6+I6 -> 0 | K6: =SUM(H6:I6) -> 0 | L6: =SUMIF(gol_C,B6,tunc_esel) -> 0 | M6: =SUMIF(gol_C,B6,tunc_um) -> 0 | N6: =SUMIF(gol_C,B6,tunc_fu) -> 0 | O6: 0 | P6: =SUMIF(gol_C,B6,tunc_ber) -> 0 | Q6: =SUMIF(gol_C,B6,tunc_paj) -> 0 | R6: =SUMIF(gol_C,B6,tunc_bulat) -> 0 | S6: =L6+M6+N6+O6+P6+Q6+R6 -> 0 | T6: =S6+J6 -> 0 | U6: =Q6 -> 0 | V6: 0 | W6: =SUMIF(gol_C,B6,iwpC1) -> 0 | X6: =SUMIF(gol_C,B6,iwpc8) -> 0 | Y6: =SUM(U6:X6) -> 0 | Z6: =T6-Y6 -> 0
B7: IV/B | C7: =SUMIF(gol_C,B7,peg_c) -> 0 | D7: =IFERROR(VLOOKUP(B7,data,3,FALSE), 0) -> 0 | E7: =IFERROR(VLOOKUP(B7,data,4,FALSE), 0) -> 0 | F7: =SUM(C7:E7) -> 0 | G7: =SUMIF(gol_C,B7,gapok_c) -> 0 | H7: =SUMIF(gol_C,B7,tunis_C) -> 0 | I7: =SUMIF(gol_C,B7,tuna_c) -> 0 | J7: =G7+H7+I7 -> 0 | K7: =SUM(H7:I7) -> 0 | L7: =SUMIF(gol_C,B7,tunc_esel) -> 0 | M7: =SUMIF(gol_C,B7,tunc_um) -> 0 | N7: =SUMIF(gol_C,B7,tunc_fu) -> 0 | O7: 0 | P7: =SUMIF(gol_C,B7,tunc_ber) -> 0 | Q7: =SUMIF(gol_C,B7,tunc_paj) -> 0 | R7: =SUMIF(gol_C,B7,tunc_bulat) -> 0 | S7: =L7+M7+N7+O7+P7+Q7+R7 -> 0 | T7: =S7+J7 -> 0 | U7: =Q7 -> 0 | V7: 0 | W7: =SUMIF(gol_C,B7,iwpC1) -> 0 | X7: =SUMIF(gol_C,B7,iwpc8) -> 0 | Y7: =SUM(U7:X7) -> 0 | Z7: =T7-Y7 -> 0
B8: IV/C | C8: =SUMIF(gol_C,B8,peg_c) -> 0 | D8: =IFERROR(VLOOKUP(B8,data,3,FALSE), 0) -> 0 | E8: =IFERROR(VLOOKUP(B8,data,4,FALSE), 0) -> 0 | F8: =SUM(C8:E8) -> 0 | G8: =SUMIF(gol_C,B8,gapok_c) -> 0 | H8: =SUMIF(gol_C,B8,tunis_C) -> 0 | I8: =SUMIF(gol_C,B8,tuna_c) -> 0 | J8: =G8+H8+I8 -> 0 | K8: =SUM(H8:I8) -> 0 | L8: =SUMIF(gol_C,B8,tunc_esel) -> 0 | M8: =SUMIF(gol_C,B8,tunc_um) -> 0 | N8: =SUMIF(gol_C,B8,tunc_fu) -> 0 | O8: 0 | P8: =SUMIF(gol_C,B8,tunc_ber) -> 0 | Q8: =SUMIF(gol_C,B8,tunc_paj) -> 0 | R8: =SUMIF(gol_C,B8,tunc_bulat) -> 0 | S8: =L8+M8+N8+O8+P8+Q8+R8 -> 0 | T8: =S8+J8 -> 0 | U8: =Q8 -> 0 | V8: 0 | W8: =SUMIF(gol_C,B8,iwpC1) -> 0 | X8: =SUMIF(gol_C,B8,iwpc8) -> 0 | Y8: =SUM(U8:X8) -> 0 | Z8: =T8-Y8 -> 0
B9: IV/D | C9: =SUMIF(gol_C,B9,peg_c) -> 0 | D9: =IFERROR(VLOOKUP(B9,data,3,FALSE), 0) -> 0 | E9: =IFERROR(VLOOKUP(B9,data,4,FALSE), 0) -> 0 | F9: =SUM(C9:E9) -> 0 | G9: =SUMIF(gol_C,B9,gapok_c) -> 0 | H9: =SUMIF(gol_C,B9,tunis_C) -> 0 | I9: =SUMIF(gol_C,B9,tuna_c) -> 0 | J9: =G9+H9+I9 -> 0 | K9: =SUM(H9:I9) -> 0 | L9: =SUMIF(gol_C,B9,tunc_esel) -> 0 | M9: =SUMIF(gol_C,B9,tunc_um) -> 0 | N9: =SUMIF(gol_C,B9,tunc_fu) -> 0 | O9: 0 | P9: =SUMIF(gol_C,B9,tunc_ber) -> 0 | Q9: =SUMIF(gol_C,B9,tunc_paj) -> 0 | R9: =SUMIF(gol_C,B9,tunc_bulat) -> 0 | S9: =L9+M9+N9+O9+P9+Q9+R9 -> 0 | T9: =S9+J9 -> 0 | U9: =Q9 -> 0 | V9: 0 | W9: =SUMIF(gol_C,B9,iwpC1) -> 0 | X9: =SUMIF(gol_C,B9,iwpc8) -> 0 | Y9: =SUM(U9:X9) -> 0 | Z9: =T9-Y9 -> 0
B10: III | C10: =SUM(C11:C14) -> 0 | D10: =SUM(D11:D14) -> 0 | E10: =SUM(E11:E14) -> 0 | F10: =SUM(F11:F14) -> 0 | G10: =SUM(G11:G14) -> 0 | H10: =SUM(H11:H14) -> 0 | I10: =SUM(I11:I14) -> 0 | J10: =G10+H10+I10 -> 0 | K10: =SUM(K11:K14) -> 0 | L10: =SUM(L11:L14) -> 0 | M10: =SUM(M11:M14) -> 0 | N10: =SUM(N11:N14) -> 0 | O10: =SUM(O11:O14) -> 0 | P10: =SUM(P11:P14) -> 0 | Q10: =SUM(Q11:Q14) -> 0 | R10: =SUM(R11:R14) -> 0 | S10: =L10+M10+N10+O10+P10+Q10+R10 -> 0 | T10: =S10+J10 -> 0 | U10: =SUM(U11:U14) -> 0 | V10: =SUM(V11:V14) -> 0 | W10: =SUM(W11:W14) -> 0 | X10: =SUM(X11:X14) -> 0 | Y10: =SUM(U10:X10) -> 0 | Z10: =T10-Y10 -> 0
B11: III/A | C11: =SUMIF(gol_C,B11,peg_c) -> 0 | D11: =SUMIF(gol_C,B11,istri_C) -> 0 | E11: =SUMIF(gol_C,B11,anak_C) -> 0 | F11: =SUM(C11:E11) -> 0 | G11: =SUMIF(gol_C,B11,gapok_c) -> 0 | H11: =SUMIF(gol_C,B11,tunis_C) -> 0 | I11: =SUMIF(gol_C,B11,tuna_c) -> 0 | J11: =G11+H11+I11 -> 0 | K11: =SUM(H11:I11) -> 0 | L11: =SUMIF(gol_C,B11,tunc_esel) -> 0 | M11: =SUMIF(gol_C,B11,tunc_um) -> 0 | N11: =SUMIF(gol_C,B11,tunc_fu) -> 0 | O11: 0 | P11: =SUMIF(gol_C,B11,tunc_ber) -> 0 | Q11: =SUMIF(gol_C,B11,tunc_paj) -> 0 | R11: =SUMIF(gol_C,B11,tunc_bulat) -> 0 | S11: =L11+M11+N11+O11+P11+Q11+R11 -> 0 | T11: =S11+J11 -> 0 | U11: =Q11 -> 0 | V11: 0 | W11: =SUMIF(gol_C,B11,iwpC1) -> 0 | X11: =SUMIF(gol_C,B11,iwpc8) -> 0 | Y11: =SUM(U11:X11) -> 0 | Z11: =Y11+T11 -> 0
B12: III/B | C12: =SUMIF(gol_C,B12,peg_c) -> 0 | D12: =SUMIF(gol_C,B12,istri_C) -> 0 | E12: =SUMIF(gol_C,B12,anak_C) -> 0 | F12: =SUM(C12:E12) -> 0 | G12: =SUMIF(gol_C,B12,gapok_c) -> 0 | H12: =SUMIF(gol_C,B12,tunis_C) -> 0 | I12: =SUMIF(gol_C,B12,tuna_c) -> 0 | J12: =G12+H12+I12 -> 0 | K12: =SUM(H12:I12) -> 0 | L12: =SUMIF(gol_C,B12,tunc_esel) -> 0 | M12: =SUMIF(gol_C,B12,tunc_um) -> 0 | N12: =SUMIF(gol_C,B12,tunc_fu) -> 0 | O12: 0 | P12: =SUMIF(gol_C,B12,tunc_ber) -> 0 | Q12: =SUMIF(gol_C,B12,tunc_paj) -> 0 | R12: =SUMIF(gol_C,B12,tunc_bulat) -> 0 | S12: =L12+M12+N12+O12+P12+Q12+R12 -> 0 | T12: =S12+J12 -> 0 | U12: =Q12 -> 0 | V12: 0 | W12: =SUMIF(gol_C,B12,iwpC1) -> 0 | X12: =SUMIF(gol_C,B12,iwpc8) -> 0 | Y12: =SUM(U12:X12) -> 0 | Z12: =Y12+T12 -> 0
B13: III/C | C13: =SUMIF(gol_C,B13,peg_c) -> 0 | D13: =SUMIF(gol_C,B13,istri_C) -> 0 | E13: =SUMIF(gol_C,B13,anak_C) -> 0 | F13: =SUM(C13:E13) -> 0 | G13: =SUMIF(gol_C,B13,gapok_c) -> 0 | H13: =SUMIF(gol_C,B13,tunis_C) -> 0 | I13: =SUMIF(gol_C,B13,tuna_c) -> 0 | J13: =G13+H13+I13 -> 0 | K13: =SUM(H13:I13) -> 0 | L13: =SUMIF(gol_C,B13,tunc_esel) -> 0 | M13: =SUMIF(gol_C,B13,tunc_um) -> 0 | N13: =SUMIF(gol_C,B13,tunc_fu) -> 0 | O13: 0 | P13: =SUMIF(gol_C,B13,tunc_ber) -> 0 | Q13: =SUMIF(gol_C,B13,tunc_paj) -> 0 | R13: =SUMIF(gol_C,B13,tunc_bulat) -> 0 | S13: =L13+M13+N13+O13+P13+Q13+R13 -> 0 | T13: =S13+J13 -> 0 | U13: =Q13 -> 0 | V13: 0 | W13: =SUMIF(gol_C,B13,iwpC1) -> 0 | X13: =SUMIF(gol_C,B13,iwpc8) -> 0 | Y13: =SUM(U13:X13) -> 0 | Z13: =Y13+T13 -> 0
B14: III/D | C14: =SUMIF(gol_C,B14,peg_c) -> 0 | D14: =SUMIF(gol_C,B14,istri_C) -> 0 | E14: =SUMIF(gol_C,B14,anak_C) -> 0 | F14: =SUM(C14:E14) -> 0 | G14: =SUMIF(gol_C,B14,gapok_c) -> 0 | H14: =SUMIF(gol_C,B14,tunis_C) -> 0 | I14: =SUMIF(gol_C,B14,tuna_c) -> 0 | J14: =G14+H14+I14 -> 0 | K14: =SUM(H14:I14) -> 0 | L14: =SUMIF(gol_C,B14,tunc_esel) -> 0 | M14: =SUMIF(gol_C,B14,tunc_um) -> 0 | N14: =SUMIF(gol_C,B14,tunc_fu) -> 0 | O14: 0 | P14: =SUMIF(gol_C,B14,tunc_ber) -> 0 | Q14: =SUMIF(gol_C,B14,tunc_paj) -> 0 | R14: =SUMIF(gol_C,B14,tunc_bulat) -> 0 | S14: =L14+M14+N14+O14+P14+Q14+R14 -> 0 | T14: =S14+J14 -> 0 | U14: =Q14 -> 0 | V14: 0 | W14: =SUMIF(gol_C,B14,iwpC1) -> 0 | X14: =SUMIF(gol_C,B14,iwpc8) -> 0 | Y14: =SUM(U14:X14) -> 0 | Z14: =Y14+T14 -> 0
B15: I I | C15: =SUM(C16:C19) -> 2 | D15: =SUM(D16:D19) -> 2 | E15: =SUM(E16:E19) -> 3 | F15: =SUM(F16:F19) -> 7 | G15: =SUM(G16:G19) -> 5717600 | H15: =SUM(H16:H19) -> 571760 | I15: =SUM(I16:I19) -> 171528 | J15: =G15+H15+I15 -> 6460888 | K15: =SUM(K16:K19) -> 743288 | L15: =SUM(L16:L19) -> 0 | M15: =SUM(M16:M19) -> 0 | N15: =SUM(N16:N19) -> 710000 | O15: =SUM(O16:O19) -> 0 | P15: =SUM(P16:P19) -> 506940 | Q15: =SUM(Q16:Q19) -> 0 | R15: =SUM(R16:R19) -> 81 | S15: =L15+M15+N15+O15+P15+Q15+R15 -> 1217021 | T15: =S15+J15 -> 7677909 | U15: =SUM(U16:U19) -> 0 | V15: =SUM(V16:V19) -> 0 | W15: =SUM(W16:W19) -> 71709 | X15: =SUM(X16:X19) -> 0 | Y15: =SUM(U15:X15) -> 71709 | Z15: =T15-Y15 -> 7606200
B16: II/A | C16: =SUMIF(gol_C,B16,peg_c) -> 0 | D16: =SUMIF(gol_C,B16,istri_C) -> 0 | E16: =SUMIF(gol_C,B16,anak_C) -> 0 | F16: =SUM(C16:E16) -> 0 | G16: =SUMIF(gol_C,B16,gapok_c) -> 0 | H16: =SUMIF(gol_C,B16,tunis_C) -> 0 | I16: =SUMIF(gol_C,B16,tuna_c) -> 0 | J16: =G16+H16+I16 -> 0 | K16: =SUM(H16:I16) -> 0 | L16: =SUMIF(gol_C,B16,tunc_esel) -> 0 | M16: =SUMIF(gol_C,B16,tunc_um) -> 0 | N16: =SUMIF(gol_C,B16,tunc_fu) -> 0 | O16: 0 | P16: =SUMIF(gol_C,B16,tunc_ber) -> 0 | Q16: =SUMIF(gol_C,B16,tunc_paj) -> 0 | R16: =SUMIF(gol_C,B16,tunc_bulat) -> 0 | S16: =L16+M16+N16+O16+P16+Q16+R16 -> 0 | T16: =S16+J16 -> 0 | U16: =Q16 -> 0 | V16: 0 | W16: =SUMIF(gol_C,B16,iwpC1) -> 0 | X16: =SUMIF(gol_C,B16,iwpc8) -> 0 | Y16: =SUM(U16:X16) -> 0 | Z16: =Y16+T16 -> 0
B17: II/B | C17: =SUMIF(gol_C,B17,peg_c) -> 0 | D17: =SUMIF(gol_C,B17,istri_C) -> 0 | E17: =SUMIF(gol_C,B17,anak_C) -> 0 | F17: =SUM(C17:E17) -> 0 | G17: =SUMIF(gol_C,B17,gapok_c) -> 0 | H17: =SUMIF(gol_C,B17,tunis_C) -> 0 | I17: =SUMIF(gol_C,B17,tuna_c) -> 0 | J17: =G17+H17+I17 -> 0 | K17: =SUM(H17:I17) -> 0 | L17: =SUMIF(gol_C,B17,tunc_esel) -> 0 | M17: =SUMIF(gol_C,B17,tunc_um) -> 0 | N17: =SUMIF(gol_C,B17,tunc_fu) -> 0 | O17: 0 | P17: =SUMIF(gol_C,B17,tunc_ber) -> 0 | Q17: =SUMIF(gol_C,B17,tunc_paj) -> 0 | R17: =SUMIF(gol_C,B17,tunc_bulat) -> 0 | S17: =L17+M17+N17+O17+P17+Q17+R17 -> 0 | T17: =S17+J17 -> 0 | U17: =Q17 -> 0 | V17: 0 | W17: =SUMIF(gol_C,B17,iwpC1) -> 0 | X17: =SUMIF(gol_C,B17,iwpc8) -> 0 | Y17: =SUM(U17:X17) -> 0 | Z17: =Y17+T17 -> 0
B18: II/C | C18: =SUMIF(gol_C,B18,peg_c) -> 2 | D18: =SUMIF(gol_C,B18,istri_C) -> 2 | E18: =SUMIF(gol_C,B18,anak_C) -> 3 | F18: =SUM(C18:E18) -> 7 | G18: =SUMIF(gol_C,B18,gapok_c) -> 5717600 | H18: =SUMIF(gol_C,B18,tunis_C) -> 571760 | I18: =SUMIF(gol_C,B18,tuna_c) -> 171528 | J18: =G18+H18+I18 -> 6460888 | K18: =SUM(H18:I18) -> 743288 | L18: =SUMIF(gol_C,B18,tunc_esel) -> 0 | M18: =SUMIF(gol_C,B18,tunc_um) -> 0 | N18: =SUMIF(gol_C,B18,tunc_fu) -> 710000 | O18: 0 | P18: =SUMIF(gol_C,B18,tunc_ber) -> 506940 | Q18: =SUMIF(gol_C,B18,tunc_paj) -> 0 | R18: =SUMIF(gol_C,B18,tunc_bulat) -> 81 | S18: =L18+M18+N18+O18+P18+Q18+R18 -> 1217021 | T18: =S18+J18 -> 7677909 | U18: =Q18 -> 0 | V18: 0 | W18: =SUMIF(gol_C,B18,iwpC1) -> 71709 | X18: =SUMIF(gol_C,B18,iwpc8) -> 0 | Y18: =SUM(U18:X18) -> 71709 | Z18: =Y18+T18 -> 7749618
B19: II/D | C19: =SUMIF(gol_C,B19,peg_c) -> 0 | D19: =SUMIF(gol_C,B19,istri_C) -> 0 | E19: =SUMIF(gol_C,B19,anak_C) -> 0 | F19: =SUM(C19:E19) -> 0 | G19: =SUMIF(gol_C,B19,gapok_c) -> 0 | H19: =SUMIF(gol_C,B19,tunis_C) -> 0 | I19: =SUMIF(gol_C,B19,tuna_c) -> 0 | J19: =G19+H19+I19 -> 0 | K19: =SUM(H19:I19) -> 0 | L19: =SUMIF(gol_C,B19,tunc_esel) -> 0 | M19: =SUMIF(gol_C,B19,tunc_um) -> 0 | N19: =SUMIF(gol_C,B19,tunc_fu) -> 0 | O19: 0 | P19: =SUMIF(gol_C,B19,tunc_ber) -> 0 | Q19: =SUMIF(gol_C,B19,tunc_paj) -> 0 | R19: =SUMIF(gol_C,B19,tunc_bulat) -> 0 | S19: =L19+M19+N19+O19+P19+Q19+R19 -> 0 | T19: =S19+J19 -> 0 | U19: =Q19 -> 0 | V19: 0 | W19: =SUMIF(gol_C,B19,iwpC1) -> 0 | X19: =SUMIF(gol_C,B19,iwpc8) -> 0 | Y19: =SUM(U19:X19) -> 0 | Z19: =Y19+T19 -> 0
B20: I | C20: =SUM(C21:C24) -> 0 | D20: =SUM(D21:D24) -> 0 | E20: =SUM(E21:E24) -> 0 | F20: =SUM(F21:F24) -> 0 | G20: =SUM(G21:G24) -> 0 | H20: =SUM(H21:H24) -> 0 | I20: =SUM(I21:I24) -> 0 | J20: =G20+H20+I20 -> 0 | K20: =SUM(K21:K24) -> 0 | L20: =SUM(L21:L24) -> 0 | M20: =SUM(M21:M24) -> 0 | N20: =SUM(N21:N24) -> 0 | O20: =SUM(O21:O24) -> 0 | P20: =SUM(P21:P24) -> 0 | Q20: =SUM(Q21:Q24) -> 0 | R20: =SUM(R21:R24) -> 0 | S20: =L20+M20+N20+O20+P20+Q20+R20 -> 0 | T20: =S20+J20 -> 0 | U20: =SUM(U21:U24) -> 0 | V20: =SUM(V21:V24) -> 0 | W20: =SUM(W21:W24) -> 0 | X20: =SUM(X21:X24) -> 0 | Y20: =SUM(U20:X20) -> 0 | Z20: =T20-Y20 -> 0
B21: I/A | C21: =IFERROR(VLOOKUP(B21,data,2,FALSE), 0) -> 0 | D21: =IFERROR(VLOOKUP(B21,dada,3,FALSE),"0") -> 0 | E21: =IFERROR(VLOOKUP(B21,dada,4,FALSE),"0") -> 0 | F21: =SUM(C21:E21) -> 0 | G21: =SUMIF(gol_C,B21,gapok_c) -> 0 | H21: =SUMIF(gol_C,B21,tunis_C) -> 0 | I21: =SUMIF(gol_C,B21,tuna_c) -> 0 | J21: =G21+H21+I21 -> 0 | K21: =SUM(H21:I21) -> 0 | L21: =SUMIF(gol_C,B21,tunc_esel) -> 0 | M21: =SUMIF(gol_C,B21,tunc_um) -> 0 | N21: =SUMIF(gol_C,B21,tunc_fu) -> 0 | O21: 0 | P21: =SUMIF(gol_C,B21,tunc_ber) -> 0 | Q21: =SUMIF(gol_C,B21,tunc_paj) -> 0 | R21: =SUMIF(gol_C,B21,tunc_bulat) -> 0 | S21: =L21+M21+N21+O21+P21+Q21+R21 -> 0 | T21: =S21+J21 -> 0 | U21: =Q21 -> 0 | V21: 0 | W21: =SUMIF(gol_C,B21,iwpC1) -> 0 | X21: =SUMIF(gol_C,B21,iwpc8) -> 0 | Y21: =SUM(U21:X21) -> 0 | Z21: =Y21+T21 -> 0
B22: I/B | C22: =IFERROR(VLOOKUP(B22,data,2,FALSE), 0) -> 0 | D22: =IFERROR(VLOOKUP(B22,dada,3,FALSE),"0") -> 0 | E22: =IFERROR(VLOOKUP(B22,dada,4,FALSE),"0") -> 0 | F22: =SUM(C22:E22) -> 0 | G22: =SUMIF(gol_C,B22,gapok_c) -> 0 | H22: =SUMIF(gol_C,B22,tunis_C) -> 0 | I22: =SUMIF(gol_C,B22,tuna_c) -> 0 | J22: =G22+H22+I22 -> 0 | K22: =SUM(H22:I22) -> 0 | L22: =SUMIF(gol_C,B22,tunc_esel) -> 0 | M22: =SUMIF(gol_C,B22,tunc_um) -> 0 | N22: =SUMIF(gol_C,B22,tunc_fu) -> 0 | O22: 0 | P22: =SUMIF(gol_C,B22,tunc_ber) -> 0 | Q22: =SUMIF(gol_C,B22,tunc_paj) -> 0 | R22: =SUMIF(gol_C,B22,tunc_bulat) -> 0 | S22: =L22+M22+N22+O22+P22+Q22+R22 -> 0 | T22: =S22+J22 -> 0 | U22: =Q22 -> 0 | V22: 0 | W22: =SUMIF(gol_C,B22,iwpC1) -> 0 | X22: =SUMIF(gol_C,B22,iwpc8) -> 0 | Y22: =SUM(U22:X22) -> 0 | Z22: =Y22+T22 -> 0
B23: I/C | C23: =IFERROR(VLOOKUP(B23,data,2,FALSE), 0) -> 0 | D23: =IFERROR(VLOOKUP(B23,dada,3,FALSE),"0") -> 0 | E23: =IFERROR(VLOOKUP(B23,dada,4,FALSE),"0") -> 0 | F23: =SUM(C23:E23) -> 0 | G23: =SUMIF(gol_C,B23,gapok_c) -> 0 | H23: =SUMIF(gol_C,B23,tunis_C) -> 0 | I23: =SUMIF(gol_C,B23,tuna_c) -> 0 | J23: =G23+H23+I23 -> 0 | K23: =SUM(H23:I23) -> 0 | L23: =SUMIF(gol_C,B23,tunc_esel) -> 0 | M23: =SUMIF(gol_C,B23,tunc_um) -> 0 | N23: =SUMIF(gol_C,B23,tunc_fu) -> 0 | O23: 0 | P23: =SUMIF(gol_C,B23,tunc_ber) -> 0 | Q23: =SUMIF(gol_C,B23,tunc_paj) -> 0 | R23: =SUMIF(gol_C,B23,tunc_bulat) -> 0 | S23: =L23+M23+N23+O23+P23+Q23+R23 -> 0 | T23: =S23+J23 -> 0 | U23: =Q23 -> 0 | V23: 0 | W23: =SUMIF(gol_C,B23,iwpC1) -> 0 | X23: =SUMIF(gol_C,B23,iwpc8) -> 0 | Y23: =SUM(U23:X23) -> 0 | Z23: =Y23+T23 -> 0
B24: I/D | C24: =IFERROR(VLOOKUP(B24,data,2,FALSE), 0) -> 0 | D24: =IFERROR(VLOOKUP(B24,dada,3,FALSE),"0") -> 0 | E24: =IFERROR(VLOOKUP(B24,dada,4,FALSE),"0") -> 0 | F24: =SUM(C24:E24) -> 0 | G24: =SUMIF(gol_C,B24,gapok_c) -> 0 | H24: =SUMIF(gol_C,B24,tunis_C) -> 0 | I24: =SUMIF(gol_C,B24,tuna_c) -> 0 | J24: =G24+H24+I24 -> 0 | K24: =SUM(H24:I24) -> 0 | L24: =SUMIF(gol_C,B24,tunc_esel) -> 0 | M24: =SUMIF(gol_C,B24,tunc_um) -> 0 | N24: =SUMIF(gol_C,B24,tunc_fu) -> 0 | O24: 0 | P24: =SUMIF(gol_C,B24,tunc_ber) -> 0 | Q24: =SUMIF(gol_C,B24,tunc_paj) -> 0 | R24: =SUMIF(gol_C,B24,tunc_bulat) -> 0 | S24: =L24+M24+N24+O24+P24+Q24+R24 -> 0 | T24: =S24+J24 -> 0 | U24: =Q24 -> 0 | V24: 0 | W24: =SUMIF(gol_C,B24,iwpC1) -> 0 | X24: =SUMIF(gol_C,B24,iwpc8) -> 0 | Y24: =SUM(U24:X24) -> 0 | Z24: =Y24+T24 -> 0
B25: JML | C25: =C20+C15+C10+C5 -> 2 | D25: =D20+D15+D10+D5 -> 2 | E25: =E20+E15+E10+E5 -> 3 | F25: =F20+F15+F10+F5 -> 7 | G25: =G20+G15+G10+G5 -> 5717600 | H25: =H20+H15+H10+H5 -> 571760 | I25: =I20+I15+I10+I5 -> 171528 | J25: =J20+J15+J10+J5 -> 6460888 | ... Z25: =Z20+Z15+Z10+Z5 -> 7606200

Sheet ENTRI DATA
B1: MEI 2025
A2: No | B2: Nama | C2: Golongan | D2: Golongan | E2: Peg. | F2: Istri | G2: Anak | H2: gaji pokok | I2: tunj. Istri | J2: tunj. Anak | K2: Tunj. Eselon | L2: Tunj. Umum | M2: fungsional | N2: khusus | O2: Tunj. Beras | P2: Tunj. Pajak | Q2: pembulatan | R2: JML Kotor | S2: IWP 1% | T2: IWP 8% | U2: JML Pot.
C3: 1 | D3: 1 | E3: 2 | F3: 3 | G3: 4 | H3: 5 | I3: 6 | J3: 7 | K3: 8 | L3: 9 | M3: 10 | N3: 11 | O3: 12 | P3: 13 | Q3: 14 | R3: 15 | S3: 16 | T3: 17 | U3: 18
A4: 1 | B4: HARDI AGUNADI A.Md | C4: VII | D4: II/C | E4: 1 | F4: 1 | G4: 1 | H4: 2858800 | I4: =(H4*10%)*F4 -> 285880 | J4: =(H4*2%)*G4 -> 57176 | K4: 0 | L4: 0 | M4: 360000 | N4: 0 | O4: =72420*SUM(E4:G4) -> 217260 | P4: 0 | Q4: 3 | R4: =SUM(H4:Q4) -> 3779119 | S4: 35619 | T4: 0 | U4: =P4+S4+T4 -> 35619 | V4: =R4-U4 -> 3743500
A5: 2 | B5: EKO HADININGSIH A.Md | C5: VII | D5: II/C | E5: 1 | F5: 1 | G5: 2 | H5: 2858800 | I5: =(H5*10%)*F5 -> 285880 | J5: =(H5*2%)*G5 -> 114352 | K5: 0 | L5: 0 | M5: 350000 | N5: 0 | O5: =72420*SUM(E5:G5) -> 289680 | P5: 0 | Q5: 78 | R5: =SUM(H5:Q5) -> 3898790 | S5: 36090 | T5: 0 | U5: =P5+S5+T5 -> 36090 | V5: =R5-U5 -> 3862700
A6: 3 | I6: =(H6*10%)*F6 -> 0 | J6: =(H6*2%)*G6 -> 0 | K6: 0 | L6: 0 | M6: 0 | N6: 0 | O6: =72420*SUM(E6:G6) -> 0 | P6: 0 | Q6: 0 | R6: =SUM(H6:Q6) -> 0 | S6: 0 | T6: 0 | U6: =P6+S6+T6 -> 0
A7: 4 | I7: =(H7*10%)*F7 -> 0 | J7: =(H7*2%)*G7 -> 0 | K7: 0 | L7: 0 | M7: 0 | N7: 0 | O7: =72420*SUM(E7:G7) -> 0 | P7: 0 | Q7: 0 | R7: =SUM(H7:Q7) -> 0 | S7: 0 | T7: 0 | U7: =P7+S7+T7 -> 0
A8: 5 | I8: =(H8*10%)*F8 -> 0 | J8: =(H8*2%)*G8 -> 0 | K8: 0 | L8: 0 | M8: 0 | N8: 0 | O8: =72420*SUM(E8:G8) -> 0 | P8: 0 | Q8: 0 | R8: =SUM(H8:Q8) -> 0 | S8: 0 | T8: 0 | U8: =P8+S8+T8 -> 0
A9: 6 | I9: =(H9*10%)*F9 -> 0 | J9: =(H9*2%)*G9 -> 0 | K9: 0 | L9: 0 | M9: 0 | N9: 0 | O9: =72420*SUM(E9:G9) -> 0 | P9: 0 | Q9: 0 | R9: =SUM(H9:Q9) -> 0 | S9: 0 | T9: 0 | U9: =P9+S9+T9 -> 0
A10: 7 | I10: =(H10*10%)*F10 -> 0 | J10: =(H10*2%)*G10 -> 0 | K10: 0 | L10: 0 | M10: 0 | N10: 0 | O10: =72420*SUM(E10:G10) -> 0 | P10: 0 | Q10: 0 | R10: =SUM(H10:Q10) -> 0 | S10: 0 | T10: 0 | U10: =P10+S10+T10 -> 0
A11: 8 | I11: =(H11*10%)*F11 -> 0 | J11: =(H11*2%)*G11 -> 0 | K11: 0 | L11: 0 | M11: 0 | N11: 0 | O11: =72420*SUM(E11:G11) -> 0 | P11: 0 | Q11: 0 | R11: =SUM(H11:Q11) -> 0 | S11: 0 | T11: 0 | U11: =P11+S11+T11 -> 0
A12: 9 | I12: =(H12*10%)*F12 -> 0 | J12: =(H12*2%)*G12 -> 0 | K12: 0 | L12: 0 | M12: 0 | N12: 0 | O12: =72420*SUM(E12:G12) -> 0 | P12: 0 | Q12: 0 | R12: =SUM(H12:Q12) -> 0 | S12: 0 | T12: 0 | U12: =P12+S12+T12 -> 0
A13: 10 | I13: =(H13*10%)*F13 -> 0 | J13: =(H13*2%)*G13 -> 0 | K13: 0 | L13: 0 | M13: 0 | N13: 0 | O13: =72420*SUM(E13:G13) -> 0 | P13: 0 | Q13: 0 | R13: =SUM(H13:Q13) -> 0 | S13: 0 | T13: 0 | U13: =P13+S13+T13 -> 0
A14: 11 | I14: =(H14*10%)*F14 -> 0 | J14: =(H14*2%)*G14 -> 0 | K14: 0 | L14: 0 | M14: 0 | N14: 0 | O14: =72420*SUM(E14:G14) -> 0 | P14: 0 | Q14: 0 | R14: =SUM(H14:Q14) -> 0 | S14: 0 | T14: 0 | U14: =P14+S14+T14 -> 0
A15: 12 | I15: =(H15*10%)*F15 -> 0 | J15: =(H15*2%)*G15 -> 0 | K15: 0 | L15: 0 | M15: 0 | N15: 0 | O15: =72420*SUM(E15:G15) -> 0 | P15: 0 | Q15: 0 | R15: =SUM(H15:Q15) -> 0 | S15: 0 | T15: 0 | U15: =P15+S15+T15 -> 0
A16: 13 | I16: =(H16*10%)*F16 -> 0 | J16: =(H16*2%)*G16 -> 0 | K16: 0 | L16: 0 | M16: 0 | N16: 0 | O16: =72420*SUM(E16:G16) -> 0 | P16: 0 | Q16: 0 | R16: =SUM(H16:Q16) -> 0 | S16: 0 | T16: 0 | U16: =P16+S16+T16 -> 0
A17: 14 | I17: =(H17*10%)*F17 -> 0 | J17: =(H17*2%)*G17 -> 0 | K17: 0 | L17: 0 | M17: 0 | N17: 0 | O17: =72420*SUM(E17:G17) -> 0 | P17: 0 | Q17: 0 | R17: =SUM(H17:Q17) -> 0 | S17: 0 | T17: 0 | U17: =P17+S17+T17 -> 0
... A19: 16 | I19: =(H19*10%)*F19 -> 0 | J19: =(H19*2%)*G19 -> 0 | K19: 0 | L19: 0 | M19: 0 | N19: 0 | O19: =72420*SUM(E19:G19) -> 0 | P19: 0 | Q19: 0 | R19: =SUM(H19:Q19) -> 0 | S19: 0 | T19: 0 | U19: =P19+S19+T19 -> 0
A20: 17
A21: 18
A22: 19
A23: 20
A24: 21
E25: =SUM(E4:E24) -> 2 | F25: =SUM(F4:F24) -> 2 | G25: =SUM(G4:G24) -> 3 | H25: =SUM(H4:H24) -> 5717600 | I25: =SUM(I4:I24) -> 571760 | J25: =SUM(J4:J24) -> 171528 | K25: =SUM(K4:K24) -> 0 | L25: =SUM(L4:L24) -> 0 | ... U25: =SUM(U4:U24) -> 71709

Sheet DATA UMUM
